Workbook

Sheet Pedido
C2: ESTRATÉGICO VII | E2: Dealer: | F2: 1079 | G2: ICMS %: | H2: 0.12 | J2: Total R$: | K2: =SUM(K5:K900) -> 0
B4: Seq. | C4: Partnumber | D4: Descrição | E4: Modalid. | F4: Tipo de Pedido | G4: Preço Rev. c/ IPI (Atual) | H4: Preço Rev. c/ IPI (Promo.) | I4: Desconto | J4: Qtde | K4: Valor R$ | M4: Múltiplo Embalagem
B5: =Preços!A2 -> 1 | C5: =Preços!B2 -> 04C-115-105-E | D5: =Preços!C2 -> BOMBA OLEO | E5: PAC | F5: Peças | G5: =IFERROR(IF(OR($F$2="",$H$2=""),0,VLOOKUP($C5,Preços!$B:$Q,VLOOKUP($H$2,Preços!$S$1:$U$8,2,0),0)),0) -> 358.60421 | H5: =IFERROR(IF(OR($F$2="",$H$2=""),0,VLOOKUP($C5,Preços!$B:$Q,VLOOKUP($H$2,Preços!$S$1:$U$8,3,0),0)),0) -> 233.80619 | I5: =IFERROR(((H5/G5)-1)*-1,0) -> 0.34801047 | K5: =H5*J5 -> 0 | M5: =Preços!R2 -> 1
B6: =Preços!A3 -> 2 | C6: =Preços!B3 -> 04E-115-105-BM | D6: =Preços!C3 -> BOMBA OLEO | E6: PAC | F6: Peças | G6: =IFERROR(IF(OR($F$2="",$H$2=""),0,VLOOKUP($C6,Preços!$B:$Q,VLOOKUP($H$2,Preços!$S$1:$U$8,2,0),0)),0) -> 2289.1035 | H6: =IFERROR(IF(OR($F$2="",$H$2=""),0,VLOOKUP($C6,Preços!$B:$Q,VLOOKUP($H$2,Preços!$S$1:$U$8,3,0),0)),0) -> 1517.8238 | I6: =IFERROR(((H6/G6)-1)*-1,0) -> 0.33693528 | K6: =H6*J6 -> 0 | M6: =Preços!R3 -> 1
B7: =Preços!A4 -> 3 | C7: =Preços!B4 -> 04E-115-105-M | D7: =Preços!C4 -> BOMBA OLEO | E7: PAC | F7: Peças | G7: =IFERROR(IF(OR($F$2="",$H$2=""),0,VLOOKUP($C7,Preços!$B:$Q,VLOOKUP($H$2,Preços!$S$1:$U$8,2,0),0)),0) -> 359.36238 | H7: =IFERROR(IF(OR($F$2="",$H$2=""),0,VLOOKUP($C7,Preços!$B:$Q,VLOOKUP($H$2,Preços!$S$1:$U$8,3,0),0)),0) -> 248.37116 | I7: =IFERROR(((H7/G7)-1)*-1,0) -> 0.30885598 | K7: =H7*J7 -> 0 | M7: =Preços!R4 -> 1
B8: =Preços!A5 -> 4 | C8: =Preços!B5 -> 030-115-636-D | D8: =Preços!C5 -> GUIA | E8: PAC | F8: Peças | G8: =IFERROR(IF(OR($F$2="",$H$2=""),0,VLOOKUP($C8,Preços!$B:$Q,VLOOKUP($H$2,Preços!$S$1:$U$8,2,0),0)),0) -> 22.400701 | H8: =IFERROR(IF(OR($F$2="",$H$2=""),0,VLOOKUP($C8,Preços!$B:$Q,VLOOKUP($H$2,Preços!$S$1:$U$8,3,0),0)),0) -> 15.040254 | I8: =IFERROR(((H8/G8)-1)*-1,0) -> 0.32858111 | K8: =H8*J8 -> 0 | M8: =Preços!R5 -> 10
B9: =Preços!A6 -> 5 | C9: =Preços!B6 -> 059-121-012-B | D9: =Preços!C6 -> BOMBA AGUA | E9: PAC | F9: Peças | G9: =IFERROR(IF(OR($F$2="",$H$2=""),0,VLOOKUP($C9,Preços!$B:$Q,VLOOKUP($H$2,Preços!$S$1:$U$8,2,0),0)),0) -> 1845.6386 | H9: =IFERROR(IF(OR($F$2="",$H$2=""),0,VLOOKUP($C9,Preços!$B:$Q,VLOOKUP($H$2,Preços!$S$1:$U$8,3,0),0)),0) -> 1149.8665 | I9: =IFERROR(((H9/G9)-1)*-1,0) -> 0.37698176 | K9: =H9*J9 -> 0 | M9: =Preços!R6 -> 1
B10: =Preços!A7 -> 6 | C10: =Preços!B7 -> 2GB-121-203-J | D10: =Preços!C7 -> VENTILADOR | E10: PAC | F10: Peças | G10: =IFERROR(IF(OR($F$2="",$H$2=""),0,VLOOKUP($C10,Preços!$B:$Q,VLOOKUP($H$2,Preços!$S$1:$U$8,2,0),0)),0) -> 1913.2063 | H10: =IFERROR(IF(OR($F$2="",$H$2=""),0,VLOOKUP($C10,Preços!$B:$Q,VLOOKUP($H$2,Preços!$S$1:$U$8,3,0),0)),0) -> 1083.6286 | I10: =IFERROR(((H10/G10)-1)*-1,0) -> 0.43360601 | K10: =H10*J10 -> 0 | M10: =Preços!R7 -> 1
B11: =Preços!A8 -> 7 | C11: =Preços!B8 -> 5QM-121-203-L | D11: =Preços!C8 -> VENTILADOR | E11: PAC | F11: Peças | G11: =IFERROR(IF(OR($F$2="",$H$2=""),0,VLOOKUP($C11,Preços!$B:$Q,VLOOKUP($H$2,Preços!$S$1:$U$8,2,0),0)),0) -> 2402.273 | H11: =IFERROR(IF(OR($F$2="",$H$2=""),0,VLOOKUP($C11,Preços!$B:$Q,VLOOKUP($H$2,Preços!$S$1:$U$8,3,0),0)),0) -> 1524.2857 | I11: =IFERROR(((H11/G11)-1)*-1,0) -> 0.3654819 | K11: =H11*J11 -> 0 | M11: =Preços!R8 -> 1
B12: =Preços!A9 -> 8 | C12: =Preços!B9 -> 5U0-121-207-B | D12: =Preços!C9 -> DEFLETOR | E12: PAC | F12: Peças | G12: =IFERROR(IF(OR($F$2="",$H$2=""),0,VLOOKUP($C12,Preços!$B:$Q,VLOOKUP($H$2,Preços!$S$1:$U$8,2,0),0)),0) -> 315.11238 | H12: =IFERROR(IF(OR($F$2="",$H$2=""),0,VLOOKUP($C12,Preços!$B:$Q,VLOOKUP($H$2,Preços!$S$1:$U$8,3,0),0)),0) -> 239.17223 | I12: =IFERROR(((H12/G12)-1)*-1,0) -> 0.24099387 | K12: =H12*J12 -> 0 | M12: =Preços!R9 -> 1
B13: =Preços!A10 -> 9 | C13: =Preços!B10 -> 2QB-121-251-A | D13: =Preços!C10 -> RADIADOR | E13: PAC | F13: Peças | G13: =IFERROR(IF(OR($F$2="",$H$2=""),0,VLOOKUP($C13,Preços!$B:$Q,VLOOKUP($H$2,Preços!$S$1:$U$8,2,0),0)),0) -> 1149.99 | H13: =IFERROR(IF(OR($F$2="",$H$2=""),0,VLOOKUP($C13,Preços!$B:$Q,VLOOKUP($H$2,Preços!$S$1:$U$8,3,0),0)),0) -> 910.69426 | I13: =IFERROR(((H13/G13)-1)*-1,0) -> 0.20808503 | K13: =H13*J13 -> 0 | M13: =Preços!R10 -> 1
B14: =Preços!A11 -> 10 | C14: =Preços!B11 -> 5U0-121-253-C | D14: =Preços!C11 -> RADIADOR | E14: PAC | F14: Peças | G14: =IFERROR(IF(OR($F$2="",$H$2=""),0,VLOOKUP($C14,Preços!$B:$Q,VLOOKUP($H$2,Preços!$S$1:$U$8,2,0),0)),0) -> 592.48131 | H14: =IFERROR(IF(OR($F$2="",$H$2=""),0,VLOOKUP($C14,Preços!$B:$Q,VLOOKUP($H$2,Preços!$S$1:$U$8,3,0),0)),0) -> 275.96796 | I14: =IFERROR(((H14/G14)-1)*-1,0) -> 0.5342166 | K14: =H14*J14 -> 0 | M14: =Preços!R11 -> 1
B15: =Preços!A12 -> 11 | C15: =Preços!B12 -> 2Q0-121-321-A | D15: =Preços!C12 -> TAMPA | E15: PAC | F15: Peças | G15: =IFERROR(IF(OR($F$2="",$H$2=""),0,VLOOKUP($C15,Preços!$B:$Q,VLOOKUP($H$2,Preços!$S$1:$U$8,2,0),0)),0) -> 207.06519 | H15: =IFERROR(IF(OR($F$2="",$H$2=""),0,VLOOKUP($C15,Preços!$B:$Q,VLOOKUP($H$2,Preços!$S$1:$U$8,3,0),0)),0) -> 126.30134 | I15: =IFERROR(((H15/G15)-1)*-1,0) -> 0.39004071 | K15: =H15*J15 -> 0 | M15: =Preços!R12 -> 1
B16: =Preços!A13 -> 12 | C16: =Preços!B13 -> 5U0-121-407-C | D16: =Preços!C13 -> RESERVATOR | E16: PAC | F16: Peças | G16: =IFERROR(IF(OR($F$2="",$H$2=""),0,VLOOKUP($C16,Preços!$B:$Q,VLOOKUP($H$2,Preços!$S$1:$U$8,2,0),0)),0) -> 56.146495 | H16: =IFERROR(IF(OR($F$2="",$H$2=""),0,VLOOKUP($C16,Preços!$B:$Q,VLOOKUP($H$2,Preços!$S$1:$U$8,3,0),0)),0) -> 37.163685 | I16: =IFERROR(((H16/G16)-1)*-1,0) -> 0.33809431 | K16: =H16*J16 -> 0 | M16: =Preços!R13 -> 1
... B46: =Preços!A43 -> 42 | C46: =Preços!B43 -> 2GX-857-706- -RAA | D46: =Preços!C43 -> CINTO 3 PT | E46: PAC | F46: Peças | G46: =IFERROR(IF(OR($F$2="",$H$2=""),0,VLOOKUP($C46,Preços!$B:$Q,VLOOKUP($H$2,Preços!$S$1:$U$8,2,0),0)),0) -> 398.58084 | H46: =IFERROR(IF(OR($F$2="",$H$2=""),0,VLOOKUP($C46,Preços!$B:$Q,VLOOKUP($H$2,Preços!$S$1:$U$8,3,0),0)),0) -> 294.36582 | I46: =IFERROR(((H46/G46)-1)*-1,0) -> 0.2614652 | K46: =H46*J46 -> 0 | M46: =Preços!R43 -> 1
B47: =Preços!A44 -> 0 | C47: =Preços!B44 -> 0 | D47: =Preços!C44 -> 0 | E47: PAC | F47: =IF(VLOOKUP(C47,#REF!,5,0)="Acessórios","Acessórios","Peças") -> #REF! | G47: =IFERROR(IF(OR($F$2="",$H$2=""),0,VLOOKUP($C47,Preços!$B:$Q,VLOOKUP($H$2,Preços!$S$1:$U$8,2,0),0)),0) -> 0 | H47: =IFERROR(IF(OR($F$2="",$H$2=""),0,VLOOKUP($C47,Preços!$B:$Q,VLOOKUP($H$2,Preços!$S$1:$U$8,3,0),0)),0) -> 0 | I47: =IFERROR(((H47/G47)-1)*-1,0) -> 0 | K47: =H47*J47 -> 0 | M47: =Preços!R44 -> 0
B48: =Preços!A45 -> 0 | C48: =Preços!B45 -> 0 | D48: =Preços!C45 -> 0 | E48: PAC | F48: =IF(VLOOKUP(C48,#REF!,5,0)="Acessórios","Acessórios","Peças") -> #REF! | G48: =IFERROR(IF(OR($F$2="",$H$2=""),0,VLOOKUP($C48,Preços!$B:$Q,VLOOKUP($H$2,Preços!$S$1:$U$8,2,0),0)),0) -> 0 | H48: =IFERROR(IF(OR($F$2="",$H$2=""),0,VLOOKUP($C48,Preços!$B:$Q,VLOOKUP($H$2,Preços!$S$1:$U$8,3,0),0)),0) -> 0 | I48: =IFERROR(((H48/G48)-1)*-1,0) -> 0 | K48: =H48*J48 -> 0 | M48: =Preços!R45 -> 0
B49: =Preços!A46 -> 0 | C49: =Preços!B46 -> 0 | D49: =Preços!C46 -> 0 | E49: PAC | F49: =IF(VLOOKUP(C49,#REF!,5,0)="Acessórios","Acessórios","Peças") -> #REF! | G49: =IFERROR(IF(OR($F$2="",$H$2=""),0,VLOOKUP($C49,Preços!$B:$Q,VLOOKUP($H$2,Preços!$S$1:$U$8,2,0),0)),0) -> 0 | H49: =IFERROR(IF(OR($F$2="",$H$2=""),0,VLOOKUP($C49,Preços!$B:$Q,VLOOKUP($H$2,Preços!$S$1:$U$8,3,0),0)),0) -> 0 | I49: =IFERROR(((H49/G49)-1)*-1,0) -> 0 | K49: =H49*J49 -> 0 | M49: =Preços!R46 -> 0
B50: =Preços!A47 -> 0 | C50: =Preços!B47 -> 0 | D50: =Preços!C47 -> 0 | E50: PAC | F50: =IF(VLOOKUP(C50,#REF!,5,0)="Acessórios","Acessórios","Peças") -> #REF! | G50: =IFERROR(IF(OR($F$2="",$H$2=""),0,VLOOKUP($C50,Preços!$B:$Q,VLOOKUP($H$2,Preços!$S$1:$U$8,2,0),0)),0) -> 0 | H50: =IFERROR(IF(OR($F$2="",$H$2=""),0,VLOOKUP($C50,Preços!$B:$Q,VLOOKUP($H$2,Preços!$S$1:$U$8,3,0),0)),0) -> 0 | I50: =IFERROR(((H50/G50)-1)*-1,0) -> 0 | K50: =H50*J50 -> 0 | M50: =Preços!R47 -> 0
B51: =Preços!A48 -> 0 | C51: =Preços!B48 -> 0 | D51: =Preços!C48 -> 0 | E51: PAC | F51: =IF(VLOOKUP(C51,#REF!,5,0)="Acessórios","Acessórios","Peças") -> #REF! | G51: =IFERROR(IF(OR($F$2="",$H$2=""),0,VLOOKUP($C51,Preços!$B:$Q,VLOOKUP($H$2,Preços!$S$1:$U$8,2,0),0)),0) -> 0 | H51: =IFERROR(IF(OR($F$2="",$H$2=""),0,VLOOKUP($C51,Preços!$B:$Q,VLOOKUP($H$2,Preços!$S$1:$U$8,3,0),0)),0) -> 0 | I51: =IFERROR(((H51/G51)-1)*-1,0) -> 0 | K51: =H51*J51 -> 0 | M51: =Preços!R48 -> 0
B52: =Preços!A49 -> 0 | C52: =Preços!B49 -> 0 | D52: =Preços!C49 -> 0 | E52: PAC | F52: =IF(VLOOKUP(C52,#REF!,5,0)="Acessórios","Acessórios","Peças") -> #REF! | G52: =IFERROR(IF(OR($F$2="",$H$2=""),0,VLOOKUP($C52,Preços!$B:$Q,VLOOKUP($H$2,Preços!$S$1:$U$8,2,0),0)),0) -> 0 | H52: =IFERROR(IF(OR($F$2="",$H$2=""),0,VLOOKUP($C52,Preços!$B:$Q,VLOOKUP($H$2,Preços!$S$1:$U$8,3,0),0)),0) -> 0 | I52: =IFERROR(((H52/G52)-1)*-1,0) -> 0 | K52: =H52*J52 -> 0 | M52: =Preços!R49 -> 0
B53: =Preços!A50 -> 0 | C53: =Preços!B50 -> 0 | D53: =Preços!C50 -> 0 | E53: PAC | F53: =IF(VLOOKUP(C53,#REF!,5,0)="Acessórios","Acessórios","Peças") -> #REF! | G53: =IFERROR(IF(OR($F$2="",$H$2=""),0,VLOOKUP($C53,Preços!$B:$Q,VLOOKUP($H$2,Preços!$S$1:$U$8,2,0),0)),0) -> 0 | H53: =IFERROR(IF(OR($F$2="",$H$2=""),0,VLOOKUP($C53,Preços!$B:$Q,VLOOKUP($H$2,Preços!$S$1:$U$8,3,0),0)),0) -> 0 | I53: =IFERROR(((H53/G53)-1)*-1,0) -> 0 | K53: =H53*J53 -> 0 | M53: =Preços!R50 -> 0
B54: =Preços!A51 -> 0 | C54: =Preços!B51 -> 0 | D54: =Preços!C51 -> 0 | E54: PAC | F54: =IF(VLOOKUP(C54,#REF!,5,0)="Acessórios","Acessórios","Peças") -> #REF! | G54: =IFERROR(IF(OR($F$2="",$H$2=""),0,VLOOKUP($C54,Preços!$B:$Q,VLOOKUP($H$2,Preços!$S$1:$U$8,2,0),0)),0) -> 0 | H54: =IFERROR(IF(OR($F$2="",$H$2=""),0,VLOOKUP($C54,Preços!$B:$Q,VLOOKUP($H$2,Preços!$S$1:$U$8,3,0),0)),0) -> 0 | I54: =IFERROR(((H54/G54)-1)*-1,0) -> 0 | K54: =H54*J54 -> 0 | M54: =Preços!R51 -> 0
B55: =Preços!A52 -> 0 | C55: =Preços!B52 -> 0 | D55: =Preços!C52 -> 0 | E55: PAC | F55: =IF(VLOOKUP(C55,#REF!,5,0)="Acessórios","Acessórios","Peças") -> #REF! | G55: =IFERROR(IF(OR($F$2="",$H$2=""),0,VLOOKUP($C55,Preços!$B:$Q,VLOOKUP($H$2,Preços!$S$1:$U$8,2,0),0)),0) -> 0 | H55: =IFERROR(IF(OR($F$2="",$H$2=""),0,VLOOKUP($C55,Preços!$B:$Q,VLOOKUP($H$2,Preços!$S$1:$U$8,3,0),0)),0) -> 0 | I55: =IFERROR(((H55/G55)-1)*-1,0) -> 0 | K55: =H55*J55 -> 0 | M55: =Preços!R52 -> 0
B56: =Preços!A53 -> 0 | C56: =Preços!B53 -> 0 | D56: =Preços!C53 -> 0 | E56: PAC | F56: =IF(VLOOKUP(C56,#REF!,5,0)="Acessórios","Acessórios","Peças") -> #REF! | G56: =IFERROR(IF(OR($F$2="",$H$2=""),0,VLOOKUP($C56,Preços!$B:$Q,VLOOKUP($H$2,Preços!$S$1:$U$8,2,0),0)),0) -> 0 | H56: =IFERROR(IF(OR($F$2="",$H$2=""),0,VLOOKUP($C56,Preços!$B:$Q,VLOOKUP($H$2,Preços!$S$1:$U$8,3,0),0)),0) -> 0 | I56: =IFERROR(((H56/G56)-1)*-1,0) -> 0 | K56: =H56*J56 -> 0 | M56: =Preços!R53 -> 0
B57: =Preços!A54 -> 0 | C57: =Preços!B54 -> 0 | D57: =Preços!C54 -> 0 | E57: PAC | F57: =IF(VLOOKUP(C57,#REF!,5,0)="Acessórios","Acessórios","Peças") -> #REF! | G57: =IFERROR(IF(OR($F$2="",$H$2=""),0,VLOOKUP($C57,Preços!$B:$Q,VLOOKUP($H$2,Preços!$S$1:$U$8,2,0),0)),0) -> 0 | H57: =IFERROR(IF(OR($F$2="",$H$2=""),0,VLOOKUP($C57,Preços!$B:$Q,VLOOKUP($H$2,Preços!$S$1:$U$8,3,0),0)),0) -> 0 | I57: =IFERROR(((H57/G57)-1)*-1,0) -> 0 | K57: =H57*J57 -> 0 | M57: =Preços!R54 -> 0
B58: =Preços!A55 -> 0 | C58: =Preços!B55 -> 0 | D58: =Preços!C55 -> 0 | E58: PAC | F58: =IF(VLOOKUP(C58,#REF!,5,0)="Acessórios","Acessórios","Peças") -> #REF! | G58: =IFERROR(IF(OR($F$2="",$H$2=""),0,VLOOKUP($C58,Preços!$B:$Q,VLOOKUP($H$2,Preços!$S$1:$U$8,2,0),0)),0) -> 0 | H58: =IFERROR(IF(OR($F$2="",$H$2=""),0,VLOOKUP($C58,Preços!$B:$Q,VLOOKUP($H$2,Preços!$S$1:$U$8,3,0),0)),0) -> 0 | I58: =IFERROR(((H58/G58)-1)*-1,0) -> 0 | K58: =H58*J58 -> 0 | M58: =Preços!R55 -> 0
... B404: =Preços!A401 -> 0 | C404: =Preços!B401 -> 0 | D404: =Preços!C401 -> 0 | E404: PAC | F404: =IF(VLOOKUP(C404,#REF!,5,0)="Acessórios","Acessórios","Peças") -> #REF! | G404: =IFERROR(IF(OR($F$2="",$H$2=""),0,VLOOKUP($C404,Preços!$B:$Q,VLOOKUP($H$2,Preços!$S$1:$U$8,2,0),0)),0) -> 0 | H404: =IFERROR(IF(OR($F$2="",$H$2=""),0,VLOOKUP($C404,Preços!$B:$Q,VLOOKUP($H$2,Preços!$S$1:$U$8,3,0),0)),0) -> 0 | I404: =IFERROR(((H404/G404)-1)*-1,0) -> 0 | K404: =H404*J404 -> 0 | M404: =Preços!R401 -> 0
B405: =Preços!A402 -> 0
B406: =Preços!A403 -> 0
B407: =Preços!A404 -> 0
B408: =Preços!A405 -> 0
B409: =Preços!A406 -> 0
B410: =Preços!A407 -> 0
B411: =Preços!A408 -> 0
B412: =Preços!A409 -> 0
B413: =Preços!A410 -> 0
B414: =Preços!A411 -> 0
B415: =Preços!A412 -> 0
B416: =Preços!A413 -> 0
...

Sheet Preços
A1: Seq | B1: nº Peça | C1: Descrição | D1: Net Price | E1: Rev_c_IPI - ICMS 0% | F1: Rev_c_IPI - ICMS 7% | G1: Rev_c_IPI - ICMS 12% | H1: Rev_c_IPI - ICMS 18% | I1: VDM | J1: Previsão de Vd s/ Ação | K1: Net Price | L1: Rev_c_IPI - ICMS 0% | M1: Rev_c_IPI - ICMS 7% | N1: Rev_c_IPI - ICMS 12% | O1: Rev_c_IPI - ICMS 18% | P1: Proposta Vd | Q1: Variação Net % | R1: Mutiplo de venda | S1: 0 | T1: 4 | U1: 11
A2: 1 | B2: 04C-115-105-E | C2: BOMBA OLEO | D2: 260.14 | E2: 309.08464 | F2: 336.16339 | G2: 358.60421 | H2: 389.83244 | I2: 12.571429 | J2: 1.0057143 | K2: 169.60856 | L2: 201.51995 | M2: 219.17501 | N2: 233.80619 | O2: 254.16667 | P2: 218.61 | Q2: -0.34801047 | R2: 1 | S2: 0.07 | T2: 5 | U2: 12
A3: 2 | B3: 04E-115-105-BM | C3: BOMBA OLEO | D3: 1660.57 | E3: 1973.0018 | F3: 2145.8555 | G3: 2289.1035 | H3: 2488.4449 | I3: 0.85714286 | J3: 0.068571429 | K3: 1101.0654 | L3: 1308.2278 | M3: 1422.8411 | N3: 1517.8238 | O3: 1650 | P3: 75.74 | Q3: -0.33693528 | R3: 1 | S3: 0.12 | T3: 6 | U3: 13
A4: 3 | B4: 04E-115-105-M | C4: BOMBA OLEO | D4: 260.69 | E4: 309.73812 | F4: 336.87412 | G4: 359.36238 | H4: 390.65664 | I4: 3.2857143 | J4: 0.26285714 | K4: 180.17433 | L4: 214.07365 | M4: 232.82854 | N4: 248.37116 | O4: 270 | P4: 152.31 | Q4: -0.30885598 | R4: 1 | S4: 0.18 | T4: 7 | U4: 14
A5: 4 | B5: 030-115-636-D | C5: GUIA | D5: 16.25 | E5: 19.307394 | F5: 20.998905 | G5: 22.400701 | H5: 24.351415 | I5: 365.71429 | J5: 29.257143 | K5: 10.910557 | L5: 12.963349 | M5: 14.099061 | N5: 15.040254 | O5: 16.35 | P5: 3450.28 | Q5: -0.32858111 | R5: 10
A6: 5 | B6: 059-121-012-B | C6: BOMBA AGUA | D6: 1338.87 | E6: 1590.7748 | F6: 1730.1418 | G6: 1845.6386 | H6: 2006.3618 | I6: 0.85714286 | J6: 0.068571429 | K6: 834.14044 | L6: 991.0817 | M6: 1077.9099 | N6: 1149.8665 | O6: 1250 | P6: 10 | Q6: -0.37698176 | R6: 1
A7: 6 | B7: 2GB-121-203-J | C7: VENTILADOR | D7: 1506.65 | E7: 1660.2204 | F7: 1798.9851 | G7: 1913.2063 | H7: 2070.9966 | I7: 37.428571 | J7: 2.9942857 | K7: 853.3575 | L7: 940.33884 | M7: 1018.9343 | N7: 1083.6286 | O7: 1173 | P7: 129.67 | Q7: -0.43360601 | R7: 1
A8: 7 | B8: 5QM-121-203-L | C8: VENTILADOR | D8: 1891.79 | E8: 2084.6171 | F8: 2258.8537 | G8: 2402.273 | H8: 2600.3986 | I8: 3.2857143 | J8: 0.26285714 | K8: 1200.375 | L8: 1322.7273 | M8: 1433.2836 | N8: 1524.2857 | O8: 1650 | P8: 18.05 | Q8: -0.3654819 | R8: 1
A9: 8 | B9: 5U0-121-207-B | C9: DEFLETOR | D9: 228.59 | E9: 271.59859 | F9: 295.39321 | G9: 315.11238 | H9: 342.55323 | I9: 78.714286 | J9: 6.2971429 | K9: 173.50121 | L9: 206.14499 | M9: 224.20526 | N9: 239.17223 | O9: 260 | P9: 686.12 | Q9: -0.24099387 | R9: 1
A10: 9 | B10: 2QB-121-251-A | C10: RADIADOR | D10: 834.23 | E10: 991.18812 | F10: 1078.0256 | G10: 1149.99 | H10: 1250.1342 | I10: 130.14286 | J10: 10.411429 | K10: 660.63923 | L10: 784.93671 | M10: 853.70463 | N10: 910.69426 | O10: 990 | P10: 140.36 | Q10: -0.20808503 | R10: 1
A11: 10 | B11: 5U0-121-253-C | C11: RADIADOR | D11: 429.8 | E11: 510.66571 | F11: 555.40488 | G11: 592.48131 | H11: 644.0762 | I11: 91.285714 | J11: 7.3028571 | K11: 200.1937 | L11: 237.85961 | M11: 258.69837 | N11: 275.96796 | O11: 300 | P11: 547.31 | Q11: -0.5342166 | R11: 1
A12: 11 | B12: 2Q0-121-321-A | C12: TAMPA | D12: 150.21 | E12: 178.47161 | F12: 194.10742 | G12: 207.06519 | H12: 225.09699 | I12: 97 | J12: 7.76 | K12: 91.621985 | L12: 108.86041 | M12: 118.39762 | N12: 126.30134 | O12: 137.3 | P12: 371.54 | Q12: -0.39004071 | R12: 1
A13: 12 | B13: 5U0-121-407-C | C13: RESERVATOR | D13: 40.73 | E13: 48.393239 | F13: 52.632947 | G13: 56.146495 | H13: 61.035885 | I13: 126.42857 | J13: 10.114286 | K13: 26.959419 | L13: 32.031761 | M13: 34.838048 | N13: 37.163685 | O13: 40.4 | P13: 1500.5 | Q13: -0.33809431 | R13: 1
A14: 13 | B14: 5U0-122-101 | C14: MANGUEIRA | D14: 22.79 | E14: 27.930207 | F14: 30.377159 | G14: 32.405007 | H14: 35.226923 | I14: 291 | J14: 23.28 | K14: 15.170939 | L14: 18.592693 | M14: 20.221589 | N14: 21.571495 | O14: 23.45 | P14: 4858.22 | Q14: -0.33431597 | R14: 1
A15: 14 | B15: 5Q0-122-291-BB | C15: CONEXAO | D15: 83.34 | E15: 91.834711 | F15: 99.510448 | G15: 105.82857 | H15: 114.5567 | I15: 13.857143 | J15: 1.1085714 | K15: 58.2 | L15: 64.132231 | M15: 69.492537 | N15: 73.904762 | O15: 80 | P15: 132.22 | Q15: -0.30165587 | R15: 1
A16: 15 | B16: 5Q0-122-291-DA | C16: CONEXAO | D16: 78.58 | E16: 86.589532 | F16: 93.826866 | G16: 99.784127 | H16: 108.01375 | I16: 18.571429 | J16: 1.4857143 | K16: 65.475 | L16: 72.14876 | M16: 78.179104 | N16: 83.142857 | O16: 90 | P16: 87.12 | Q16: -0.16677272 | R16: 1
... A43: 42 | B43: 2GX-857-706- -RAA | C43: CINTO 3 PT | D43: 289.14 | E43: 343.54091 | F43: 373.63836 | G43: 398.58084 | H43: 433.29035 | I43: 86.857143 | J43: 6.9485714 | K43: 213.53995 | L43: 253.71692 | M43: 275.94493 | N43: 294.36582 | O43: 320 | P43: 558.49 | Q43: -0.2614652 | R43: 1

Sheet Dealers
B1: DN | C1: REG. | D1: SAT. | E1: NOME FANTASIA
B2: 8 | C2: 2 | D2: 25 | E2: Coletto 3R
B3: 133 | C3: 2 | D3: 25 | E3: Coletto 3R
B4: 9 | C4: 3 | D4: 31 | E4: Coletto 3R
B5: 10 | C5: 3 | D5: 31 | E5: Coletto 3R
B6: 12 | C6: 2 | D6: 25 | E6: Nogueira Lins
B7: 15 | C7: 2 | D7: 25 | E7: Nogueira Lins
B8: 42 | C8: 2 | D8: 25 | E8: Nogueira Lins
B9: 48 | C9: 2 | D9: 25 | E9: Nogueira Lins
B10: 19 | C10: 2 | D10: 25 | E10: Liane
B11: 20 | C11: 2 | D11: 24 | E11: Apia
B12: 1187 | C12: 2 | D12: 24 | E12: Apia
B13: 1208 | C13: 2 | D13: 24 | E13: Apia Araras
... B459: 191 | C459: 3 | D459: 35 | E459: Felice
B460: 362 | C460: 4 | D460: 4X
